[2024-12-09T00:24:42.628+0000] {local_task_job_runner.py:123} INFO - ::group::Pre task execution logs
[2024-12-09T00:24:42.643+0000] {taskinstance.py:2613} INFO - Dependencies all met for dep_context=non-requeueable deps ti=<TaskInstance: data_ingestion_dag.task_ingest_messages_data manual__2024-12-09T00:24:41.163276+00:00 [queued]>
[2024-12-09T00:24:42.653+0000] {taskinstance.py:2613} INFO - Dependencies all met for dep_context=requeueable deps ti=<TaskInstance: data_ingestion_dag.task_ingest_messages_data manual__2024-12-09T00:24:41.163276+00:00 [queued]>
[2024-12-09T00:24:42.655+0000] {taskinstance.py:2866} INFO - Starting attempt 1 of 1
[2024-12-09T00:24:42.672+0000] {taskinstance.py:2889} INFO - Executing <Task(PythonOperator): task_ingest_messages_data> on 2024-12-09 00:24:41.163276+00:00
[2024-12-09T00:24:42.680+0000] {warnings.py:112} WARNING - /home/***/.local/lib/python3.12/site-packages/***/task/task_runner/standard_task_runner.py:70: DeprecationWarning: This process (pid=144) is multi-threaded, use of fork() may lead to deadlocks in the child.
  pid = os.fork()

[2024-12-09T00:24:42.682+0000] {standard_task_runner.py:72} INFO - Started process 146 to run task
[2024-12-09T00:24:42.682+0000] {standard_task_runner.py:104} INFO - Running: ['***', 'tasks', 'run', 'data_ingestion_dag', 'task_ingest_messages_data', 'manual__2024-12-09T00:24:41.163276+00:00', '--job-id', '41', '--raw', '--subdir', 'DAGS_FOLDER/test.py', '--cfg-path', '/tmp/tmpm0wdrws1']
[2024-12-09T00:24:42.685+0000] {standard_task_runner.py:105} INFO - Job 41: Subtask task_ingest_messages_data
[2024-12-09T00:24:42.738+0000] {task_command.py:467} INFO - Running <TaskInstance: data_ingestion_dag.task_ingest_messages_data manual__2024-12-09T00:24:41.163276+00:00 [running]> on host f69482497956
[2024-12-09T00:24:42.823+0000] {taskinstance.py:3132} INFO - Exporting env vars: AIRFLOW_CTX_DAG_OWNER='***' AIRFLOW_CTX_DAG_ID='data_ingestion_dag' AIRFLOW_CTX_TASK_ID='task_ingest_messages_data' AIRFLOW_CTX_EXECUTION_DATE='2024-12-09T00:24:41.163276+00:00' AIRFLOW_CTX_TRY_NUMBER='1' AIRFLOW_CTX_DAG_RUN_ID='manual__2024-12-09T00:24:41.163276+00:00'
[2024-12-09T00:24:42.825+0000] {taskinstance.py:731} INFO - ::endgroup::
[2024-12-09T00:24:42.837+0000] {execute.py:83} INFO - Input Notebook:  /opt/***/dataset/cleanup_messages.ipynb
[2024-12-09T00:24:42.837+0000] {execute.py:84} INFO - Output Notebook: /opt/***/dataset/output_cleanup_messages.ipynb
[2024-12-09T00:24:42.840+0000] {taskinstance.py:3311} ERROR - Task failed with exception
Traceback (most recent call last):
  File "/home/airflow/.local/lib/python3.12/site-packages/papermill/iorw.py", line 199, in read
    json.loads(path)
  File "/usr/local/lib/python3.12/json/__init__.py", line 346, in loads
    return _default_decoder.decode(s)
           ^^^^^^^^^^^^^^^^^^^^^^^^^^
  File "/usr/local/lib/python3.12/json/decoder.py", line 337, in decode
    obj, end = self.raw_decode(s, idx=_w(s, 0).end())
               ^^^^^^^^^^^^^^^^^^^^^^^^^^^^^^^^^^^^^^
  File "/usr/local/lib/python3.12/json/decoder.py", line 355, in raw_decode
    raise JSONDecodeError("Expecting value", s, err.value) from None
json.decoder.JSONDecodeError: Expecting value: line 1 column 1 (char 0)

During handling of the above exception, another exception occurred:

Traceback (most recent call last):
  File "/home/airflow/.local/lib/python3.12/site-packages/airflow/models/taskinstance.py", line 767, in _execute_task
    result = _execute_callable(context=context, **execute_callable_kwargs)
             ^^^^^^^^^^^^^^^^^^^^^^^^^^^^^^^^^^^^^^^^^^^^^^^^^^^^^^^^^^^^^
  File "/home/airflow/.local/lib/python3.12/site-packages/airflow/models/taskinstance.py", line 733, in _execute_callable
    return ExecutionCallableRunner(
           ^^^^^^^^^^^^^^^^^^^^^^^^
  File "/home/airflow/.local/lib/python3.12/site-packages/airflow/utils/operator_helpers.py", line 252, in run
    return self.func(*args, **kwargs)
           ^^^^^^^^^^^^^^^^^^^^^^^^^^
  File "/home/airflow/.local/lib/python3.12/site-packages/airflow/models/baseoperator.py", line 417, in wrapper
    return func(self, *args, **kwargs)
           ^^^^^^^^^^^^^^^^^^^^^^^^^^^
  File "/home/airflow/.local/lib/python3.12/site-packages/airflow/operators/python.py", line 238, in execute
    return_value = self.execute_callable()
                   ^^^^^^^^^^^^^^^^^^^^^^^
  File "/home/airflow/.local/lib/python3.12/site-packages/airflow/operators/python.py", line 256, in execute_callable
    return runner.run(*self.op_args, **self.op_kwargs)
           ^^^^^^^^^^^^^^^^^^^^^^^^^^^^^^^^^^^^^^^^^^^
  File "/home/airflow/.local/lib/python3.12/site-packages/airflow/utils/operator_helpers.py", line 252, in run
    return self.func(*args, **kwargs)
           ^^^^^^^^^^^^^^^^^^^^^^^^^^
  File "/opt/airflow/resources/util_read_insert_data.py", line 41, in load_excel_to_db
    cleaned_data = process_notebook_and_generate_csv(
                   ^^^^^^^^^^^^^^^^^^^^^^^^^^^^^^^^^^
  File "/opt/airflow/resources/util_read_insert_data.py", line 17, in process_notebook_and_generate_csv
    pm.execute_notebook(
  File "/home/airflow/.local/lib/python3.12/site-packages/papermill/execute.py", line 89, in execute_notebook
    nb = load_notebook_node(input_path)
         ^^^^^^^^^^^^^^^^^^^^^^^^^^^^^^
  File "/home/airflow/.local/lib/python3.12/site-packages/papermill/iorw.py", line 499, in load_notebook_node
    nb = nbformat.reads(papermill_io.read(notebook_path), as_version=4)
                        ^^^^^^^^^^^^^^^^^^^^^^^^^^^^^^^^
  File "/home/airflow/.local/lib/python3.12/site-packages/papermill/iorw.py", line 96, in read
    notebook_metadata = self.get_handler(path, extensions).read(path)
                        ^^^^^^^^^^^^^^^^^^^^^^^^^^^^^^^^^^^^^^^^^^^^^
  File "/home/airflow/.local/lib/python3.12/site-packages/papermill/iorw.py", line 203, in read
    raise e
  File "/home/airflow/.local/lib/python3.12/site-packages/papermill/iorw.py", line 193, in read
    with open(path, encoding="utf-8") as f:
         ^^^^^^^^^^^^^^^^^^^^^^^^^^^^
FileNotFoundError: [Errno 2] No such file or directory: '/opt/airflow/dataset/cleanup_messages.ipynb'
[2024-12-09T00:24:42.855+0000] {taskinstance.py:1225} INFO - Marking task as FAILED. dag_id=data_ingestion_dag, task_id=task_ingest_messages_data, run_id=manual__2024-12-09T00:24:41.163276+00:00, execution_date=20241209T002441, start_date=20241209T002442, end_date=20241209T002442
[2024-12-09T00:24:42.870+0000] {taskinstance.py:340} INFO - ::group::Post task execution logs
[2024-12-09T00:24:42.871+0000] {standard_task_runner.py:124} ERROR - Failed to execute job 41 for task task_ingest_messages_data ([Errno 2] No such file or directory: '/opt/airflow/dataset/cleanup_messages.ipynb'; 146)
Traceback (most recent call last):
  File "/home/airflow/.local/lib/python3.12/site-packages/papermill/iorw.py", line 199, in read
    json.loads(path)
  File "/usr/local/lib/python3.12/json/__init__.py", line 346, in loads
    return _default_decoder.decode(s)
           ^^^^^^^^^^^^^^^^^^^^^^^^^^
  File "/usr/local/lib/python3.12/json/decoder.py", line 337, in decode
    obj, end = self.raw_decode(s, idx=_w(s, 0).end())
               ^^^^^^^^^^^^^^^^^^^^^^^^^^^^^^^^^^^^^^
  File "/usr/local/lib/python3.12/json/decoder.py", line 355, in raw_decode
    raise JSONDecodeError("Expecting value", s, err.value) from None
json.decoder.JSONDecodeError: Expecting value: line 1 column 1 (char 0)

During handling of the above exception, another exception occurred:

Traceback (most recent call last):
  File "/home/airflow/.local/lib/python3.12/site-packages/airflow/task/task_runner/standard_task_runner.py", line 117, in _start_by_fork
    ret = args.func(args, dag=self.dag)
          ^^^^^^^^^^^^^^^^^^^^^^^^^^^^^
  File "/home/airflow/.local/lib/python3.12/site-packages/airflow/cli/cli_config.py", line 49, in command
    return func(*args, **kwargs)
           ^^^^^^^^^^^^^^^^^^^^^
  File "/home/airflow/.local/lib/python3.12/site-packages/airflow/utils/cli.py", line 116, in wrapper
    return f(*args, **kwargs)
           ^^^^^^^^^^^^^^^^^^
  File "/home/airflow/.local/lib/python3.12/site-packages/airflow/cli/commands/task_command.py", line 483, in task_run
    task_return_code = _run_task_by_selected_method(args, _dag, ti)
                       ^^^^^^^^^^^^^^^^^^^^^^^^^^^^^^^^^^^^^^^^^^^^
  File "/home/airflow/.local/lib/python3.12/site-packages/airflow/cli/commands/task_command.py", line 256, in _run_task_by_selected_method
    return _run_raw_task(args, ti)
           ^^^^^^^^^^^^^^^^^^^^^^^
  File "/home/airflow/.local/lib/python3.12/site-packages/airflow/cli/commands/task_command.py", line 341, in _run_raw_task
    return ti._run_raw_task(
           ^^^^^^^^^^^^^^^^^
  File "/home/airflow/.local/lib/python3.12/site-packages/airflow/utils/session.py", line 97, in wrapper
    return func(*args, session=session, **kwargs)
           ^^^^^^^^^^^^^^^^^^^^^^^^^^^^^^^^^^^^^^
  File "/home/airflow/.local/lib/python3.12/site-packages/airflow/models/taskinstance.py", line 3005, in _run_raw_task
    return _run_raw_task(
           ^^^^^^^^^^^^^^
  File "/home/airflow/.local/lib/python3.12/site-packages/airflow/models/taskinstance.py", line 273, in _run_raw_task
    TaskInstance._execute_task_with_callbacks(
  File "/home/airflow/.local/lib/python3.12/site-packages/airflow/models/taskinstance.py", line 3159, in _execute_task_with_callbacks
    result = self._execute_task(context, task_orig)
             ^^^^^^^^^^^^^^^^^^^^^^^^^^^^^^^^^^^^^^
  File "/home/airflow/.local/lib/python3.12/site-packages/airflow/models/taskinstance.py", line 3183, in _execute_task
    return _execute_task(self, context, task_orig)
           ^^^^^^^^^^^^^^^^^^^^^^^^^^^^^^^^^^^^^^^
  File "/home/airflow/.local/lib/python3.12/site-packages/airflow/models/taskinstance.py", line 767, in _execute_task
    result = _execute_callable(context=context, **execute_callable_kwargs)
             ^^^^^^^^^^^^^^^^^^^^^^^^^^^^^^^^^^^^^^^^^^^^^^^^^^^^^^^^^^^^^
  File "/home/airflow/.local/lib/python3.12/site-packages/airflow/models/taskinstance.py", line 733, in _execute_callable
    return ExecutionCallableRunner(
           ^^^^^^^^^^^^^^^^^^^^^^^^
  File "/home/airflow/.local/lib/python3.12/site-packages/airflow/utils/operator_helpers.py", line 252, in run
    return self.func(*args, **kwargs)
           ^^^^^^^^^^^^^^^^^^^^^^^^^^
  File "/home/airflow/.local/lib/python3.12/site-packages/airflow/models/baseoperator.py", line 417, in wrapper
    return func(self, *args, **kwargs)
           ^^^^^^^^^^^^^^^^^^^^^^^^^^^
  File "/home/airflow/.local/lib/python3.12/site-packages/airflow/operators/python.py", line 238, in execute
    return_value = self.execute_callable()
                   ^^^^^^^^^^^^^^^^^^^^^^^
  File "/home/airflow/.local/lib/python3.12/site-packages/airflow/operators/python.py", line 256, in execute_callable
    return runner.run(*self.op_args, **self.op_kwargs)
           ^^^^^^^^^^^^^^^^^^^^^^^^^^^^^^^^^^^^^^^^^^^
  File "/home/airflow/.local/lib/python3.12/site-packages/airflow/utils/operator_helpers.py", line 252, in run
    return self.func(*args, **kwargs)
           ^^^^^^^^^^^^^^^^^^^^^^^^^^
  File "/opt/airflow/resources/util_read_insert_data.py", line 41, in load_excel_to_db
    cleaned_data = process_notebook_and_generate_csv(
                   ^^^^^^^^^^^^^^^^^^^^^^^^^^^^^^^^^^
  File "/opt/airflow/resources/util_read_insert_data.py", line 17, in process_notebook_and_generate_csv
    pm.execute_notebook(
  File "/home/airflow/.local/lib/python3.12/site-packages/papermill/execute.py", line 89, in execute_notebook
    nb = load_notebook_node(input_path)
         ^^^^^^^^^^^^^^^^^^^^^^^^^^^^^^
  File "/home/airflow/.local/lib/python3.12/site-packages/papermill/iorw.py", line 499, in load_notebook_node
    nb = nbformat.reads(papermill_io.read(notebook_path), as_version=4)
                        ^^^^^^^^^^^^^^^^^^^^^^^^^^^^^^^^
  File "/home/airflow/.local/lib/python3.12/site-packages/papermill/iorw.py", line 96, in read
    notebook_metadata = self.get_handler(path, extensions).read(path)
                        ^^^^^^^^^^^^^^^^^^^^^^^^^^^^^^^^^^^^^^^^^^^^^
  File "/home/airflow/.local/lib/python3.12/site-packages/papermill/iorw.py", line 203, in read
    raise e
  File "/home/airflow/.local/lib/python3.12/site-packages/papermill/iorw.py", line 193, in read
    with open(path, encoding="utf-8") as f:
         ^^^^^^^^^^^^^^^^^^^^^^^^^^^^
FileNotFoundError: [Errno 2] No such file or directory: '/opt/airflow/dataset/cleanup_messages.ipynb'
[2024-12-09T00:24:42.899+0000] {local_task_job_runner.py:266} INFO - Task exited with return code 1
[2024-12-09T00:24:42.914+0000] {taskinstance.py:3895} INFO - 0 downstream tasks scheduled from follow-on schedule check
[2024-12-09T00:24:42.917+0000] {local_task_job_runner.py:245} INFO - ::endgroup::
