[2024-12-09T05:19:29.658+0000] {local_task_job_runner.py:123} INFO - ::group::Pre task execution logs
[2024-12-09T05:19:29.673+0000] {taskinstance.py:2613} INFO - Dependencies all met for dep_context=non-requeueable deps ti=<TaskInstance: data_pipeline_dag.task_transform_visualise manual__2024-12-09T05:16:55.618725+00:00 [queued]>
[2024-12-09T05:19:29.681+0000] {taskinstance.py:2613} INFO - Dependencies all met for dep_context=requeueable deps ti=<TaskInstance: data_pipeline_dag.task_transform_visualise manual__2024-12-09T05:16:55.618725+00:00 [queued]>
[2024-12-09T05:19:29.682+0000] {taskinstance.py:2866} INFO - Starting attempt 2 of 2
[2024-12-09T05:19:29.696+0000] {taskinstance.py:2889} INFO - Executing <Task(PythonOperator): task_transform_visualise> on 2024-12-09 05:16:55.618725+00:00
[2024-12-09T05:19:29.704+0000] {warnings.py:112} WARNING - /home/***/.local/lib/python3.12/site-packages/***/task/task_runner/standard_task_runner.py:70: DeprecationWarning: This process (pid=265) is multi-threaded, use of fork() may lead to deadlocks in the child.
  pid = os.fork()

[2024-12-09T05:19:29.706+0000] {standard_task_runner.py:72} INFO - Started process 267 to run task
[2024-12-09T05:19:29.706+0000] {standard_task_runner.py:104} INFO - Running: ['***', 'tasks', 'run', 'data_pipeline_dag', 'task_transform_visualise', 'manual__2024-12-09T05:16:55.618725+00:00', '--job-id', '62', '--raw', '--subdir', 'DAGS_FOLDER/e2e_pipeline.py', '--cfg-path', '/tmp/tmpe1v5viyn']
[2024-12-09T05:19:29.709+0000] {standard_task_runner.py:105} INFO - Job 62: Subtask task_transform_visualise
[2024-12-09T05:19:29.752+0000] {task_command.py:467} INFO - Running <TaskInstance: data_pipeline_dag.task_transform_visualise manual__2024-12-09T05:16:55.618725+00:00 [running]> on host d1b18052a0fe
[2024-12-09T05:19:29.817+0000] {taskinstance.py:3132} INFO - Exporting env vars: AIRFLOW_CTX_DAG_OWNER='***' AIRFLOW_CTX_DAG_ID='data_pipeline_dag' AIRFLOW_CTX_TASK_ID='task_transform_visualise' AIRFLOW_CTX_EXECUTION_DATE='2024-12-09T05:16:55.618725+00:00' AIRFLOW_CTX_TRY_NUMBER='2' AIRFLOW_CTX_DAG_RUN_ID='manual__2024-12-09T05:16:55.618725+00:00'
[2024-12-09T05:19:29.818+0000] {taskinstance.py:731} INFO - ::endgroup::
[2024-12-09T05:19:29.829+0000] {execute.py:83} INFO - Input Notebook:  /opt/***/dataset/transformation_visualisation.ipynb
[2024-12-09T05:19:29.830+0000] {execute.py:84} INFO - Output Notebook: /opt/***/dataset/output_transformation_visualisation.ipynb
[2024-12-09T05:19:29.886+0000] {logging_mixin.py:190} WARNING - Executing:   0%|          | 0/44 [00:00<?, ?cell/s]
[2024-12-09T05:19:31.400+0000] {clientwrap.py:44} INFO - Executing notebook with kernel: python3
[2024-12-09T05:19:31.432+0000] {logging_mixin.py:190} WARNING - Executing:   2%|2         | 1/44 [00:01<01:06,  1.54s/cell]
[2024-12-09T05:19:31.946+0000] {logging_mixin.py:190} WARNING - Executing:   9%|9         | 4/44 [00:02<00:17,  2.32cell/s]
[2024-12-09T05:19:32.142+0000] {logging_mixin.py:190} WARNING - Executing:  14%|#3        | 6/44 [00:02<00:10,  3.50cell/s]
[2024-12-09T05:19:32.244+0000] {logging_mixin.py:190} WARNING - Executing:  23%|##2       | 10/44 [00:02<00:04,  7.07cell/s]
[2024-12-09T05:19:43.050+0000] {logging_mixin.py:190} WARNING - Executing:  27%|##7       | 12/44 [00:13<00:52,  1.63s/cell]
[2024-12-09T05:19:45.163+0000] {logging_mixin.py:190} WARNING - Executing:  39%|###8      | 17/44 [00:15<00:27,  1.02s/cell]
[2024-12-09T05:19:45.277+0000] {logging_mixin.py:190} WARNING - Executing:  48%|####7     | 21/44 [00:15<00:15,  1.51cell/s]
[2024-12-09T05:19:45.407+0000] {logging_mixin.py:190} WARNING - Executing:  55%|#####4    | 24/44 [00:15<00:09,  2.05cell/s]
[2024-12-09T05:19:45.562+0000] {logging_mixin.py:190} WARNING - Executing:  61%|######1   | 27/44 [00:15<00:06,  2.76cell/s]
[2024-12-09T05:19:45.728+0000] {logging_mixin.py:190} WARNING - Executing:  68%|######8   | 30/44 [00:15<00:03,  3.66cell/s]
[2024-12-09T05:19:46.038+0000] {logging_mixin.py:190} WARNING - Executing:  80%|#######9  | 35/44 [00:16<00:01,  5.35cell/s]
[2024-12-09T05:19:46.559+0000] {logging_mixin.py:190} WARNING - Executing:  80%|#######9  | 35/44 [00:16<00:04,  2.10cell/s]
[2024-12-09T05:19:46.607+0000] {taskinstance.py:3311} ERROR - Task failed with exception
Traceback (most recent call last):
  File "/home/airflow/.local/lib/python3.12/site-packages/airflow/models/taskinstance.py", line 767, in _execute_task
    result = _execute_callable(context=context, **execute_callable_kwargs)
             ^^^^^^^^^^^^^^^^^^^^^^^^^^^^^^^^^^^^^^^^^^^^^^^^^^^^^^^^^^^^^
  File "/home/airflow/.local/lib/python3.12/site-packages/airflow/models/taskinstance.py", line 733, in _execute_callable
    return ExecutionCallableRunner(
           ^^^^^^^^^^^^^^^^^^^^^^^^
  File "/home/airflow/.local/lib/python3.12/site-packages/airflow/utils/operator_helpers.py", line 252, in run
    return self.func(*args, **kwargs)
           ^^^^^^^^^^^^^^^^^^^^^^^^^^
  File "/home/airflow/.local/lib/python3.12/site-packages/airflow/models/baseoperator.py", line 417, in wrapper
    return func(self, *args, **kwargs)
           ^^^^^^^^^^^^^^^^^^^^^^^^^^^
  File "/home/airflow/.local/lib/python3.12/site-packages/airflow/operators/python.py", line 238, in execute
    return_value = self.execute_callable()
                   ^^^^^^^^^^^^^^^^^^^^^^^
  File "/home/airflow/.local/lib/python3.12/site-packages/airflow/operators/python.py", line 256, in execute_callable
    return runner.run(*self.op_args, **self.op_kwargs)
           ^^^^^^^^^^^^^^^^^^^^^^^^^^^^^^^^^^^^^^^^^^^
  File "/home/airflow/.local/lib/python3.12/site-packages/airflow/utils/operator_helpers.py", line 252, in run
    return self.func(*args, **kwargs)
           ^^^^^^^^^^^^^^^^^^^^^^^^^^
  File "/opt/airflow/resources/util_read_insert_data.py", line 17, in process_notebook_and_generate_csv
    pm.execute_notebook(
  File "/home/airflow/.local/lib/python3.12/site-packages/papermill/execute.py", line 131, in execute_notebook
    raise_for_execution_errors(nb, output_path)
  File "/home/airflow/.local/lib/python3.12/site-packages/papermill/execute.py", line 251, in raise_for_execution_errors
    raise error
papermill.exceptions.PapermillExecutionError: 
---------------------------------------------------------------------------
Exception encountered at "In [16]":
---------------------------------------------------------------------------
ModuleNotFoundError                       Traceback (most recent call last)
Cell In[16], line 2
      1 import pandas as pd
----> 2 import matplotlib.pyplot as plt
      3 import seaborn as sns
      4 from datetime import timedelta

ModuleNotFoundError: No module named 'matplotlib'

[2024-12-09T05:19:46.623+0000] {taskinstance.py:1225} INFO - Marking task as FAILED. dag_id=data_pipeline_dag, task_id=task_transform_visualise, run_id=manual__2024-12-09T05:16:55.618725+00:00, execution_date=20241209T051655, start_date=20241209T051929, end_date=20241209T051946
[2024-12-09T05:19:46.637+0000] {taskinstance.py:340} INFO - ::group::Post task execution logs
[2024-12-09T05:19:46.637+0000] {standard_task_runner.py:124} ERROR - Failed to execute job 62 for task task_transform_visualise (
---------------------------------------------------------------------------
Exception encountered at "In [16]":
---------------------------------------------------------------------------
ModuleNotFoundError                       Traceback (most recent call last)
Cell In[16], line 2
      1 import pandas as pd
----> 2 import matplotlib.pyplot as plt
      3 import seaborn as sns
      4 from datetime import timedelta

ModuleNotFoundError: No module named 'matplotlib'
; 267)
Traceback (most recent call last):
  File "/home/airflow/.local/lib/python3.12/site-packages/airflow/task/task_runner/standard_task_runner.py", line 117, in _start_by_fork
    ret = args.func(args, dag=self.dag)
          ^^^^^^^^^^^^^^^^^^^^^^^^^^^^^
  File "/home/airflow/.local/lib/python3.12/site-packages/airflow/cli/cli_config.py", line 49, in command
    return func(*args, **kwargs)
           ^^^^^^^^^^^^^^^^^^^^^
  File "/home/airflow/.local/lib/python3.12/site-packages/airflow/utils/cli.py", line 116, in wrapper
    return f(*args, **kwargs)
           ^^^^^^^^^^^^^^^^^^
  File "/home/airflow/.local/lib/python3.12/site-packages/airflow/cli/commands/task_command.py", line 483, in task_run
    task_return_code = _run_task_by_selected_method(args, _dag, ti)
                       ^^^^^^^^^^^^^^^^^^^^^^^^^^^^^^^^^^^^^^^^^^^^
  File "/home/airflow/.local/lib/python3.12/site-packages/airflow/cli/commands/task_command.py", line 256, in _run_task_by_selected_method
    return _run_raw_task(args, ti)
           ^^^^^^^^^^^^^^^^^^^^^^^
  File "/home/airflow/.local/lib/python3.12/site-packages/airflow/cli/commands/task_command.py", line 341, in _run_raw_task
    return ti._run_raw_task(
           ^^^^^^^^^^^^^^^^^
  File "/home/airflow/.local/lib/python3.12/site-packages/airflow/utils/session.py", line 97, in wrapper
    return func(*args, session=session, **kwargs)
           ^^^^^^^^^^^^^^^^^^^^^^^^^^^^^^^^^^^^^^
  File "/home/airflow/.local/lib/python3.12/site-packages/airflow/models/taskinstance.py", line 3005, in _run_raw_task
    return _run_raw_task(
           ^^^^^^^^^^^^^^
  File "/home/airflow/.local/lib/python3.12/site-packages/airflow/models/taskinstance.py", line 273, in _run_raw_task
    TaskInstance._execute_task_with_callbacks(
  File "/home/airflow/.local/lib/python3.12/site-packages/airflow/models/taskinstance.py", line 3159, in _execute_task_with_callbacks
    result = self._execute_task(context, task_orig)
             ^^^^^^^^^^^^^^^^^^^^^^^^^^^^^^^^^^^^^^
  File "/home/airflow/.local/lib/python3.12/site-packages/airflow/models/taskinstance.py", line 3183, in _execute_task
    return _execute_task(self, context, task_orig)
           ^^^^^^^^^^^^^^^^^^^^^^^^^^^^^^^^^^^^^^^
  File "/home/airflow/.local/lib/python3.12/site-packages/airflow/models/taskinstance.py", line 767, in _execute_task
    result = _execute_callable(context=context, **execute_callable_kwargs)
             ^^^^^^^^^^^^^^^^^^^^^^^^^^^^^^^^^^^^^^^^^^^^^^^^^^^^^^^^^^^^^
  File "/home/airflow/.local/lib/python3.12/site-packages/airflow/models/taskinstance.py", line 733, in _execute_callable
    return ExecutionCallableRunner(
           ^^^^^^^^^^^^^^^^^^^^^^^^
  File "/home/airflow/.local/lib/python3.12/site-packages/airflow/utils/operator_helpers.py", line 252, in run
    return self.func(*args, **kwargs)
           ^^^^^^^^^^^^^^^^^^^^^^^^^^
  File "/home/airflow/.local/lib/python3.12/site-packages/airflow/models/baseoperator.py", line 417, in wrapper
    return func(self, *args, **kwargs)
           ^^^^^^^^^^^^^^^^^^^^^^^^^^^
  File "/home/airflow/.local/lib/python3.12/site-packages/airflow/operators/python.py", line 238, in execute
    return_value = self.execute_callable()
                   ^^^^^^^^^^^^^^^^^^^^^^^
  File "/home/airflow/.local/lib/python3.12/site-packages/airflow/operators/python.py", line 256, in execute_callable
    return runner.run(*self.op_args, **self.op_kwargs)
           ^^^^^^^^^^^^^^^^^^^^^^^^^^^^^^^^^^^^^^^^^^^
  File "/home/airflow/.local/lib/python3.12/site-packages/airflow/utils/operator_helpers.py", line 252, in run
    return self.func(*args, **kwargs)
           ^^^^^^^^^^^^^^^^^^^^^^^^^^
  File "/opt/airflow/resources/util_read_insert_data.py", line 17, in process_notebook_and_generate_csv
    pm.execute_notebook(
  File "/home/airflow/.local/lib/python3.12/site-packages/papermill/execute.py", line 131, in execute_notebook
    raise_for_execution_errors(nb, output_path)
  File "/home/airflow/.local/lib/python3.12/site-packages/papermill/execute.py", line 251, in raise_for_execution_errors
    raise error
papermill.exceptions.PapermillExecutionError: 
---------------------------------------------------------------------------
Exception encountered at "In [16]":
---------------------------------------------------------------------------
ModuleNotFoundError                       Traceback (most recent call last)
Cell In[16], line 2
      1 import pandas as pd
----> 2 import matplotlib.pyplot as plt
      3 import seaborn as sns
      4 from datetime import timedelta

ModuleNotFoundError: No module named 'matplotlib'

[2024-12-09T05:19:46.653+0000] {local_task_job_runner.py:266} INFO - Task exited with return code 1
[2024-12-09T05:19:46.674+0000] {taskinstance.py:3895} INFO - 0 downstream tasks scheduled from follow-on schedule check
[2024-12-09T05:19:46.677+0000] {local_task_job_runner.py:245} INFO - ::endgroup::
