[2024-12-09T05:22:49.927+0000] {local_task_job_runner.py:123} INFO - ::group::Pre task execution logs
[2024-12-09T05:22:49.944+0000] {taskinstance.py:2613} INFO - Dependencies all met for dep_context=non-requeueable deps ti=<TaskInstance: data_pipeline_dag.task_transform_visualise manual__2024-12-09T05:16:55.618725+00:00 [queued]>
[2024-12-09T05:22:49.953+0000] {taskinstance.py:2613} INFO - Dependencies all met for dep_context=requeueable deps ti=<TaskInstance: data_pipeline_dag.task_transform_visualise manual__2024-12-09T05:16:55.618725+00:00 [queued]>
[2024-12-09T05:22:49.954+0000] {taskinstance.py:2866} INFO - Starting attempt 3 of 3
[2024-12-09T05:22:49.973+0000] {taskinstance.py:2889} INFO - Executing <Task(PythonOperator): task_transform_visualise> on 2024-12-09 05:16:55.618725+00:00
[2024-12-09T05:22:49.980+0000] {warnings.py:112} WARNING - /home/***/.local/lib/python3.12/site-packages/***/task/task_runner/standard_task_runner.py:70: DeprecationWarning: This process (pid=68) is multi-threaded, use of fork() may lead to deadlocks in the child.
  pid = os.fork()

[2024-12-09T05:22:49.982+0000] {standard_task_runner.py:72} INFO - Started process 77 to run task
[2024-12-09T05:22:49.981+0000] {standard_task_runner.py:104} INFO - Running: ['***', 'tasks', 'run', 'data_pipeline_dag', 'task_transform_visualise', 'manual__2024-12-09T05:16:55.618725+00:00', '--job-id', '65', '--raw', '--subdir', 'DAGS_FOLDER/e2e_pipeline.py', '--cfg-path', '/tmp/tmpvu2tn1kq']
[2024-12-09T05:22:49.984+0000] {standard_task_runner.py:105} INFO - Job 65: Subtask task_transform_visualise
[2024-12-09T05:22:50.032+0000] {task_command.py:467} INFO - Running <TaskInstance: data_pipeline_dag.task_transform_visualise manual__2024-12-09T05:16:55.618725+00:00 [running]> on host 8750b0feb560
[2024-12-09T05:22:50.105+0000] {taskinstance.py:3132} INFO - Exporting env vars: AIRFLOW_CTX_DAG_OWNER='***' AIRFLOW_CTX_DAG_ID='data_pipeline_dag' AIRFLOW_CTX_TASK_ID='task_transform_visualise' AIRFLOW_CTX_EXECUTION_DATE='2024-12-09T05:16:55.618725+00:00' AIRFLOW_CTX_TRY_NUMBER='3' AIRFLOW_CTX_DAG_RUN_ID='manual__2024-12-09T05:16:55.618725+00:00'
[2024-12-09T05:22:50.106+0000] {taskinstance.py:731} INFO - ::endgroup::
[2024-12-09T05:22:50.134+0000] {execute.py:83} INFO - Input Notebook:  /opt/***/dataset/transformation_visualisation.ipynb
[2024-12-09T05:22:50.135+0000] {execute.py:84} INFO - Output Notebook: /opt/***/dataset/output_transformation_visualisation.ipynb
[2024-12-09T05:22:50.244+0000] {logging_mixin.py:190} WARNING - Executing:   0%|          | 0/44 [00:00<?, ?cell/s]
[2024-12-09T05:22:52.111+0000] {clientwrap.py:44} INFO - Executing notebook with kernel: python3
[2024-12-09T05:22:52.143+0000] {logging_mixin.py:190} WARNING - Executing:   2%|2         | 1/44 [00:01<01:21,  1.90s/cell]
[2024-12-09T05:22:52.810+0000] {logging_mixin.py:190} WARNING - Executing:   9%|9         | 4/44 [00:02<00:21,  1.85cell/s]
[2024-12-09T05:22:53.030+0000] {logging_mixin.py:190} WARNING - Executing:  14%|#3        | 6/44 [00:02<00:13,  2.84cell/s]
[2024-12-09T05:22:54.107+0000] {logging_mixin.py:190} WARNING - Executing:  25%|##5       | 11/44 [00:03<00:08,  3.72cell/s]
[2024-12-09T05:23:04.450+0000] {logging_mixin.py:190} WARNING - Executing:  27%|##7       | 12/44 [00:14<00:56,  1.76s/cell]
[2024-12-09T05:23:07.696+0000] {logging_mixin.py:190} WARNING - Executing:  39%|###8      | 17/44 [00:17<00:32,  1.19s/cell]
[2024-12-09T05:23:07.836+0000] {logging_mixin.py:190} WARNING - Executing:  50%|#####     | 22/44 [00:17<00:15,  1.43cell/s]
[2024-12-09T05:23:07.938+0000] {logging_mixin.py:190} WARNING - Executing:  57%|#####6    | 25/44 [00:17<00:09,  1.92cell/s]
[2024-12-09T05:23:08.099+0000] {logging_mixin.py:190} WARNING - Executing:  61%|######1   | 27/44 [00:17<00:07,  2.32cell/s]
[2024-12-09T05:23:08.235+0000] {logging_mixin.py:190} WARNING - Executing:  68%|######8   | 30/44 [00:17<00:04,  3.18cell/s]
[2024-12-09T05:23:08.336+0000] {logging_mixin.py:190} WARNING - Executing:  77%|#######7  | 34/44 [00:18<00:02,  4.78cell/s]
[2024-12-09T05:23:09.549+0000] {logging_mixin.py:190} WARNING - Executing:  84%|########4 | 37/44 [00:19<00:01,  3.79cell/s]
[2024-12-09T05:23:09.693+0000] {logging_mixin.py:190} WARNING - Executing:  89%|########8 | 39/44 [00:19<00:01,  4.47cell/s]
[2024-12-09T05:23:10.111+0000] {logging_mixin.py:190} WARNING - Executing:  98%|#########7| 43/44 [00:19<00:00,  5.60cell/s]
[2024-12-09T05:23:10.767+0000] {logging_mixin.py:190} WARNING - Executing:  98%|#########7| 43/44 [00:20<00:00,  2.10cell/s]
[2024-12-09T05:23:10.824+0000] {taskinstance.py:3311} ERROR - Task failed with exception
Traceback (most recent call last):
  File "/home/airflow/.local/lib/python3.12/site-packages/airflow/models/taskinstance.py", line 767, in _execute_task
    result = _execute_callable(context=context, **execute_callable_kwargs)
             ^^^^^^^^^^^^^^^^^^^^^^^^^^^^^^^^^^^^^^^^^^^^^^^^^^^^^^^^^^^^^
  File "/home/airflow/.local/lib/python3.12/site-packages/airflow/models/taskinstance.py", line 733, in _execute_callable
    return ExecutionCallableRunner(
           ^^^^^^^^^^^^^^^^^^^^^^^^
  File "/home/airflow/.local/lib/python3.12/site-packages/airflow/utils/operator_helpers.py", line 252, in run
    return self.func(*args, **kwargs)
           ^^^^^^^^^^^^^^^^^^^^^^^^^^
  File "/home/airflow/.local/lib/python3.12/site-packages/airflow/models/baseoperator.py", line 417, in wrapper
    return func(self, *args, **kwargs)
           ^^^^^^^^^^^^^^^^^^^^^^^^^^^
  File "/home/airflow/.local/lib/python3.12/site-packages/airflow/operators/python.py", line 238, in execute
    return_value = self.execute_callable()
                   ^^^^^^^^^^^^^^^^^^^^^^^
  File "/home/airflow/.local/lib/python3.12/site-packages/airflow/operators/python.py", line 256, in execute_callable
    return runner.run(*self.op_args, **self.op_kwargs)
           ^^^^^^^^^^^^^^^^^^^^^^^^^^^^^^^^^^^^^^^^^^^
  File "/home/airflow/.local/lib/python3.12/site-packages/airflow/utils/operator_helpers.py", line 252, in run
    return self.func(*args, **kwargs)
           ^^^^^^^^^^^^^^^^^^^^^^^^^^
  File "/opt/airflow/resources/util_read_insert_data.py", line 17, in process_notebook_and_generate_csv
    pm.execute_notebook(
  File "/home/airflow/.local/lib/python3.12/site-packages/papermill/execute.py", line 131, in execute_notebook
    raise_for_execution_errors(nb, output_path)
  File "/home/airflow/.local/lib/python3.12/site-packages/papermill/execute.py", line 251, in raise_for_execution_errors
    raise error
papermill.exceptions.PapermillExecutionError: 
---------------------------------------------------------------------------
Exception encountered at "In [18]":
---------------------------------------------------------------------------
ModuleNotFoundError                       Traceback (most recent call last)
Cell In[18], line 1
----> 1 import plotly.express as px
      3 query = """
      4         SELECT 
      5         s.status,
   (...)
     17         message_count DESC;
     18     """
     19 # No data vailable for last 7 days, making it 365 to visulaise

ModuleNotFoundError: No module named 'plotly'

[2024-12-09T05:23:10.838+0000] {taskinstance.py:1225} INFO - Marking task as FAILED. dag_id=data_pipeline_dag, task_id=task_transform_visualise, run_id=manual__2024-12-09T05:16:55.618725+00:00, execution_date=20241209T051655, start_date=20241209T052249, end_date=20241209T052310
[2024-12-09T05:23:10.853+0000] {taskinstance.py:340} INFO - ::group::Post task execution logs
[2024-12-09T05:23:10.854+0000] {standard_task_runner.py:124} ERROR - Failed to execute job 65 for task task_transform_visualise (
---------------------------------------------------------------------------
Exception encountered at "In [18]":
---------------------------------------------------------------------------
ModuleNotFoundError                       Traceback (most recent call last)
Cell In[18], line 1
----> 1 import plotly.express as px
      3 query = """
      4         SELECT 
      5         s.status,
   (...)
     17         message_count DESC;
     18     """
     19 # No data vailable for last 7 days, making it 365 to visulaise

ModuleNotFoundError: No module named 'plotly'
; 77)
Traceback (most recent call last):
  File "/home/airflow/.local/lib/python3.12/site-packages/airflow/task/task_runner/standard_task_runner.py", line 117, in _start_by_fork
    ret = args.func(args, dag=self.dag)
          ^^^^^^^^^^^^^^^^^^^^^^^^^^^^^
  File "/home/airflow/.local/lib/python3.12/site-packages/airflow/cli/cli_config.py", line 49, in command
    return func(*args, **kwargs)
           ^^^^^^^^^^^^^^^^^^^^^
  File "/home/airflow/.local/lib/python3.12/site-packages/airflow/utils/cli.py", line 116, in wrapper
    return f(*args, **kwargs)
           ^^^^^^^^^^^^^^^^^^
  File "/home/airflow/.local/lib/python3.12/site-packages/airflow/cli/commands/task_command.py", line 483, in task_run
    task_return_code = _run_task_by_selected_method(args, _dag, ti)
                       ^^^^^^^^^^^^^^^^^^^^^^^^^^^^^^^^^^^^^^^^^^^^
  File "/home/airflow/.local/lib/python3.12/site-packages/airflow/cli/commands/task_command.py", line 256, in _run_task_by_selected_method
    return _run_raw_task(args, ti)
           ^^^^^^^^^^^^^^^^^^^^^^^
  File "/home/airflow/.local/lib/python3.12/site-packages/airflow/cli/commands/task_command.py", line 341, in _run_raw_task
    return ti._run_raw_task(
           ^^^^^^^^^^^^^^^^^
  File "/home/airflow/.local/lib/python3.12/site-packages/airflow/utils/session.py", line 97, in wrapper
    return func(*args, session=session, **kwargs)
           ^^^^^^^^^^^^^^^^^^^^^^^^^^^^^^^^^^^^^^
  File "/home/airflow/.local/lib/python3.12/site-packages/airflow/models/taskinstance.py", line 3005, in _run_raw_task
    return _run_raw_task(
           ^^^^^^^^^^^^^^
  File "/home/airflow/.local/lib/python3.12/site-packages/airflow/models/taskinstance.py", line 273, in _run_raw_task
    TaskInstance._execute_task_with_callbacks(
  File "/home/airflow/.local/lib/python3.12/site-packages/airflow/models/taskinstance.py", line 3159, in _execute_task_with_callbacks
    result = self._execute_task(context, task_orig)
             ^^^^^^^^^^^^^^^^^^^^^^^^^^^^^^^^^^^^^^
  File "/home/airflow/.local/lib/python3.12/site-packages/airflow/models/taskinstance.py", line 3183, in _execute_task
    return _execute_task(self, context, task_orig)
           ^^^^^^^^^^^^^^^^^^^^^^^^^^^^^^^^^^^^^^^
  File "/home/airflow/.local/lib/python3.12/site-packages/airflow/models/taskinstance.py", line 767, in _execute_task
    result = _execute_callable(context=context, **execute_callable_kwargs)
             ^^^^^^^^^^^^^^^^^^^^^^^^^^^^^^^^^^^^^^^^^^^^^^^^^^^^^^^^^^^^^
  File "/home/airflow/.local/lib/python3.12/site-packages/airflow/models/taskinstance.py", line 733, in _execute_callable
    return ExecutionCallableRunner(
           ^^^^^^^^^^^^^^^^^^^^^^^^
  File "/home/airflow/.local/lib/python3.12/site-packages/airflow/utils/operator_helpers.py", line 252, in run
    return self.func(*args, **kwargs)
           ^^^^^^^^^^^^^^^^^^^^^^^^^^
  File "/home/airflow/.local/lib/python3.12/site-packages/airflow/models/baseoperator.py", line 417, in wrapper
    return func(self, *args, **kwargs)
           ^^^^^^^^^^^^^^^^^^^^^^^^^^^
  File "/home/airflow/.local/lib/python3.12/site-packages/airflow/operators/python.py", line 238, in execute
    return_value = self.execute_callable()
                   ^^^^^^^^^^^^^^^^^^^^^^^
  File "/home/airflow/.local/lib/python3.12/site-packages/airflow/operators/python.py", line 256, in execute_callable
    return runner.run(*self.op_args, **self.op_kwargs)
           ^^^^^^^^^^^^^^^^^^^^^^^^^^^^^^^^^^^^^^^^^^^
  File "/home/airflow/.local/lib/python3.12/site-packages/airflow/utils/operator_helpers.py", line 252, in run
    return self.func(*args, **kwargs)
           ^^^^^^^^^^^^^^^^^^^^^^^^^^
  File "/opt/airflow/resources/util_read_insert_data.py", line 17, in process_notebook_and_generate_csv
    pm.execute_notebook(
  File "/home/airflow/.local/lib/python3.12/site-packages/papermill/execute.py", line 131, in execute_notebook
    raise_for_execution_errors(nb, output_path)
  File "/home/airflow/.local/lib/python3.12/site-packages/papermill/execute.py", line 251, in raise_for_execution_errors
    raise error
papermill.exceptions.PapermillExecutionError: 
---------------------------------------------------------------------------
Exception encountered at "In [18]":
---------------------------------------------------------------------------
ModuleNotFoundError                       Traceback (most recent call last)
Cell In[18], line 1
----> 1 import plotly.express as px
      3 query = """
      4         SELECT 
      5         s.status,
   (...)
     17         message_count DESC;
     18     """
     19 # No data vailable for last 7 days, making it 365 to visulaise

ModuleNotFoundError: No module named 'plotly'

[2024-12-09T05:23:10.873+0000] {local_task_job_runner.py:266} INFO - Task exited with return code 1
[2024-12-09T05:23:10.900+0000] {taskinstance.py:3895} INFO - 0 downstream tasks scheduled from follow-on schedule check
[2024-12-09T05:23:10.903+0000] {local_task_job_runner.py:245} INFO - ::endgroup::
