[2024-12-09T01:19:16.716+0000] {local_task_job_runner.py:123} INFO - ::group::Pre task execution logs
[2024-12-09T01:19:16.729+0000] {taskinstance.py:2613} INFO - Dependencies all met for dep_context=non-requeueable deps ti=<TaskInstance: data_ingestion_dag.task_ingest_statuses_data manual__2024-12-09T01:19:14.466321+00:00 [queued]>
[2024-12-09T01:19:16.736+0000] {taskinstance.py:2613} INFO - Dependencies all met for dep_context=requeueable deps ti=<TaskInstance: data_ingestion_dag.task_ingest_statuses_data manual__2024-12-09T01:19:14.466321+00:00 [queued]>
[2024-12-09T01:19:16.737+0000] {taskinstance.py:2866} INFO - Starting attempt 1 of 1
[2024-12-09T01:19:16.749+0000] {taskinstance.py:2889} INFO - Executing <Task(PythonOperator): task_ingest_statuses_data> on 2024-12-09 01:19:14.466321+00:00
[2024-12-09T01:19:16.756+0000] {warnings.py:112} WARNING - /home/***/.local/lib/python3.12/site-packages/***/task/task_runner/standard_task_runner.py:70: DeprecationWarning: This process (pid=835) is multi-threaded, use of fork() may lead to deadlocks in the child.
  pid = os.fork()

[2024-12-09T01:19:16.757+0000] {standard_task_runner.py:72} INFO - Started process 839 to run task
[2024-12-09T01:19:16.758+0000] {standard_task_runner.py:104} INFO - Running: ['***', 'tasks', 'run', 'data_ingestion_dag', 'task_ingest_statuses_data', 'manual__2024-12-09T01:19:14.466321+00:00', '--job-id', '49', '--raw', '--subdir', 'DAGS_FOLDER/test.py', '--cfg-path', '/tmp/tmpbnrb3ri7']
[2024-12-09T01:19:16.762+0000] {standard_task_runner.py:105} INFO - Job 49: Subtask task_ingest_statuses_data
[2024-12-09T01:19:16.800+0000] {task_command.py:467} INFO - Running <TaskInstance: data_ingestion_dag.task_ingest_statuses_data manual__2024-12-09T01:19:14.466321+00:00 [running]> on host 58979770e908
[2024-12-09T01:19:16.905+0000] {taskinstance.py:3132} INFO - Exporting env vars: AIRFLOW_CTX_DAG_OWNER='***' AIRFLOW_CTX_DAG_ID='data_ingestion_dag' AIRFLOW_CTX_TASK_ID='task_ingest_statuses_data' AIRFLOW_CTX_EXECUTION_DATE='2024-12-09T01:19:14.466321+00:00' AIRFLOW_CTX_TRY_NUMBER='1' AIRFLOW_CTX_DAG_RUN_ID='manual__2024-12-09T01:19:14.466321+00:00'
[2024-12-09T01:19:16.907+0000] {taskinstance.py:731} INFO - ::endgroup::
[2024-12-09T01:19:16.921+0000] {execute.py:83} INFO - Input Notebook:  /opt/***/dataset/cleanup_statuses.ipynb
[2024-12-09T01:19:16.922+0000] {execute.py:84} INFO - Output Notebook: /opt/***/dataset/output_cleanup_statuses.ipynb
[2024-12-09T01:19:16.965+0000] {execute.py:97} WARNING - Passed unknown parameter: file_path
[2024-12-09T01:19:16.966+0000] {execute.py:97} WARNING - Passed unknown parameter: sheet_name
[2024-12-09T01:19:16.970+0000] {parameterize.py:114} WARNING - Input notebook does not contain a cell with tag 'parameters'
[2024-12-09T01:19:16.983+0000] {logging_mixin.py:190} WARNING - Executing:   0%|          | 0/4 [00:00<?, ?cell/s]
[2024-12-09T01:19:19.031+0000] {clientwrap.py:44} INFO - Executing notebook with kernel: python3
[2024-12-09T01:19:19.049+0000] {logging_mixin.py:190} WARNING - Executing:  25%|##5       | 1/4 [00:02<00:06,  2.07s/cell]
[2024-12-09T01:19:19.721+0000] {logging_mixin.py:190} WARNING - Executing:  50%|#####     | 2/4 [00:02<00:02,  1.25s/cell]
[2024-12-09T01:19:27.592+0000] {logging_mixin.py:190} WARNING - Executing:  75%|#######5  | 3/4 [00:10<00:04,  4.27s/cell]
[2024-12-09T01:19:28.010+0000] {logging_mixin.py:190} WARNING - Executing: 100%|##########| 4/4 [00:11<00:00,  2.75s/cell]
[2024-12-09T01:19:28.433+0000] {logging_mixin.py:190} WARNING - Executing: 100%|##########| 4/4 [00:11<00:00,  2.86s/cell]
[2024-12-09T01:19:28.569+0000] {base.py:84} INFO - Retrieving connection 'external_postgres'
[2024-12-09T01:19:29.478+0000] {taskinstance.py:3311} ERROR - Task failed with exception
Traceback (most recent call last):
  File "/home/airflow/.local/lib/python3.12/site-packages/sqlalchemy/engine/base.py", line 1890, in _execute_context
    self.dialect.do_executemany(
  File "/home/airflow/.local/lib/python3.12/site-packages/sqlalchemy/dialects/postgresql/psycopg2.py", line 982, in do_executemany
    context._psycopg2_fetched_rows = xtras.execute_values(
                                     ^^^^^^^^^^^^^^^^^^^^^
  File "/home/airflow/.local/lib/python3.12/site-packages/psycopg2/extras.py", line 1299, in execute_values
    cur.execute(b''.join(parts))
psycopg2.errors.UndefinedColumn: column "message_id" of relation "l0_statuses" does not exist
LINE 1: ...tuses (id, status, timestamp, uuid, message_uuid, message_id...
                                                             ^


The above exception was the direct cause of the following exception:

Traceback (most recent call last):
  File "/home/airflow/.local/lib/python3.12/site-packages/airflow/models/taskinstance.py", line 767, in _execute_task
    result = _execute_callable(context=context, **execute_callable_kwargs)
             ^^^^^^^^^^^^^^^^^^^^^^^^^^^^^^^^^^^^^^^^^^^^^^^^^^^^^^^^^^^^^
  File "/home/airflow/.local/lib/python3.12/site-packages/airflow/models/taskinstance.py", line 733, in _execute_callable
    return ExecutionCallableRunner(
           ^^^^^^^^^^^^^^^^^^^^^^^^
  File "/home/airflow/.local/lib/python3.12/site-packages/airflow/utils/operator_helpers.py", line 252, in run
    return self.func(*args, **kwargs)
           ^^^^^^^^^^^^^^^^^^^^^^^^^^
  File "/home/airflow/.local/lib/python3.12/site-packages/airflow/models/baseoperator.py", line 417, in wrapper
    return func(self, *args, **kwargs)
           ^^^^^^^^^^^^^^^^^^^^^^^^^^^
  File "/home/airflow/.local/lib/python3.12/site-packages/airflow/operators/python.py", line 238, in execute
    return_value = self.execute_callable()
                   ^^^^^^^^^^^^^^^^^^^^^^^
  File "/home/airflow/.local/lib/python3.12/site-packages/airflow/operators/python.py", line 256, in execute_callable
    return runner.run(*self.op_args, **self.op_kwargs)
           ^^^^^^^^^^^^^^^^^^^^^^^^^^^^^^^^^^^^^^^^^^^
  File "/home/airflow/.local/lib/python3.12/site-packages/airflow/utils/operator_helpers.py", line 252, in run
    return self.func(*args, **kwargs)
           ^^^^^^^^^^^^^^^^^^^^^^^^^^
  File "/opt/airflow/resources/util_read_insert_data.py", line 56, in load_excel_to_db
    cleaned_data.to_sql(table_name, engine, if_exists='append', index=False)
  File "/home/airflow/.local/lib/python3.12/site-packages/pandas/util/_decorators.py", line 333, in wrapper
    return func(*args, **kwargs)
           ^^^^^^^^^^^^^^^^^^^^^
  File "/home/airflow/.local/lib/python3.12/site-packages/pandas/core/generic.py", line 3008, in to_sql
    return sql.to_sql(
           ^^^^^^^^^^^
  File "/home/airflow/.local/lib/python3.12/site-packages/pandas/io/sql.py", line 788, in to_sql
    return pandas_sql.to_sql(
           ^^^^^^^^^^^^^^^^^^
  File "/home/airflow/.local/lib/python3.12/site-packages/pandas/io/sql.py", line 1958, in to_sql
    total_inserted = sql_engine.insert_records(
                     ^^^^^^^^^^^^^^^^^^^^^^^^^^
  File "/home/airflow/.local/lib/python3.12/site-packages/pandas/io/sql.py", line 1507, in insert_records
    raise err
  File "/home/airflow/.local/lib/python3.12/site-packages/pandas/io/sql.py", line 1498, in insert_records
    return table.insert(chunksize=chunksize, method=method)
           ^^^^^^^^^^^^^^^^^^^^^^^^^^^^^^^^^^^^^^^^^^^^^^^^
  File "/home/airflow/.local/lib/python3.12/site-packages/pandas/io/sql.py", line 1059, in insert
    num_inserted = exec_insert(conn, keys, chunk_iter)
                   ^^^^^^^^^^^^^^^^^^^^^^^^^^^^^^^^^^^
  File "/home/airflow/.local/lib/python3.12/site-packages/pandas/io/sql.py", line 951, in _execute_insert
    result = conn.execute(self.table.insert(), data)
             ^^^^^^^^^^^^^^^^^^^^^^^^^^^^^^^^^^^^^^^
  File "/home/airflow/.local/lib/python3.12/site-packages/sqlalchemy/engine/base.py", line 1385, in execute
    return meth(self, multiparams, params, _EMPTY_EXECUTION_OPTS)
           ^^^^^^^^^^^^^^^^^^^^^^^^^^^^^^^^^^^^^^^^^^^^^^^^^^^^^^
  File "/home/airflow/.local/lib/python3.12/site-packages/sqlalchemy/sql/elements.py", line 334, in _execute_on_connection
    return connection._execute_clauseelement(
           ^^^^^^^^^^^^^^^^^^^^^^^^^^^^^^^^^^
  File "/home/airflow/.local/lib/python3.12/site-packages/sqlalchemy/engine/base.py", line 1577, in _execute_clauseelement
    ret = self._execute_context(
          ^^^^^^^^^^^^^^^^^^^^^^
  File "/home/airflow/.local/lib/python3.12/site-packages/sqlalchemy/engine/base.py", line 1953, in _execute_context
    self._handle_dbapi_exception(
  File "/home/airflow/.local/lib/python3.12/site-packages/sqlalchemy/engine/base.py", line 2134, in _handle_dbapi_exception
    util.raise_(
  File "/home/airflow/.local/lib/python3.12/site-packages/sqlalchemy/util/compat.py", line 211, in raise_
    raise exception
  File "/home/airflow/.local/lib/python3.12/site-packages/sqlalchemy/engine/base.py", line 1890, in _execute_context
    self.dialect.do_executemany(
  File "/home/airflow/.local/lib/python3.12/site-packages/sqlalchemy/dialects/postgresql/psycopg2.py", line 982, in do_executemany
    context._psycopg2_fetched_rows = xtras.execute_values(
                                     ^^^^^^^^^^^^^^^^^^^^^
  File "/home/airflow/.local/lib/python3.12/site-packages/psycopg2/extras.py", line 1299, in execute_values
    cur.execute(b''.join(parts))
sqlalchemy.exc.ProgrammingError: (psycopg2.errors.UndefinedColumn) column "message_id" of relation "l0_statuses" does not exist
LINE 1: ...tuses (id, status, timestamp, uuid, message_uuid, message_id...
                                                             ^

[SQL: INSERT INTO l0_statuses (id, status, timestamp, uuid, message_uuid, message_id, number_id, inserted_at, updated_at) VALUES (%(id)s, %(status)s, %(timestamp)s, %(uuid)s, %(message_uuid)s, %(message_id)s, %(number_id)s, %(inserted_at)s, %(updated_at)s)]
[parameters: ({'id': 121404643, 'status': 'delivered', 'timestamp': '2020-04-02 16:34:02.369', 'uuid': '2785b584-d41d-452f-9951-1dd7bcbc40f8', 'message_uuid': '994f8115-d94f-f343-f0f7-795e18de38ae', 'message_id': 47972352, 'number_id': 182, 'inserted_at': '2020-04-02 16:34:03.997', 'updated_at': '2020-04-02 16:34:03.997'}, {'id': 121404663, 'status': 'read', 'timestamp': '2020-04-02 16:34:28.000', 'uuid': 'c2f01ea5-8985-4adf-ae12-510a72295bf9', 'message_uuid': '994f8115-d94f-f343-f0f7-795e18de38ae', 'message_id': 47972352, 'number_id': 182, 'inserted_at': '2020-04-02 16:34:39.876', 'updated_at': '2020-04-02 16:34:39.876'}, {'id': 121370160, 'status': 'sent', 'timestamp': '2020-04-01 02:31:29.303', 'uuid': 'cbdb8720-30ee-4144-96f4-6092a9b0ce42', 'message_uuid': '994f8115-d94f-f343-f0f7-795e18de38ae', 'message_id': 47972352, 'number_id': 182, 'inserted_at': '2020-04-01 02:31:29.303', 'updated_at': '2020-04-01 02:31:29.303'}, {'id': 523246060, 'status': 'delivered', 'timestamp': '2023-08-29 03:31:27.000', 'uuid': '268a88d4-0e40-49e7-ac6c-284c73bc2a67', 'message_uuid': '8847b330-1289-336e-56f5-d4909950a689', 'message_id': 497877760, 'number_id': 182, 'inserted_at': '2023-08-29 03:31:27.463', 'updated_at': '2023-08-29 03:31:27.463'}, {'id': 523245973, 'status': 'sent', 'timestamp': '2023-08-29 03:31:25.000', 'uuid': 'f3a253de-3819-4f36-83a8-143d939eef02', 'message_uuid': '8847b330-1289-336e-56f5-d4909950a689', 'message_id': 497877760, 'number_id': 182, 'inserted_at': '2023-08-29 03:31:25.843', 'updated_at': '2023-08-29 03:31:25.843'}, {'id': 523253496, 'status': 'read', 'timestamp': '2023-08-29 03:42:16.000', 'uuid': '6af45bc5-896f-41cb-8bd7-ca8d721be83d', 'message_uuid': '8847b330-1289-336e-56f5-d4909950a689', 'message_id': 497877760, 'number_id': 182, 'inserted_at': '2023-08-29 03:42:16.649', 'updated_at': '2023-08-29 03:42:16.649'}, {'id': 772422679, 'status': 'sent', 'timestamp': '2023-12-24 03:30:14.000', 'uuid': '04fd5533-5e7d-4224-9d53-f532889eb54b', 'message_uuid': '8552328f-1c69-fc6e-9249-5c721e8f55d4', 'message_id': 712312064, 'number_id': 182, 'inserted_at': '2023-12-24 03:30:15.043', 'updated_at': '2023-12-24 03:30:15.043'}, {'id': 772429767, 'status': 'read', 'timestamp': '2023-12-24 03:39:24.000', 'uuid': '87768e3a-f5b2-4cec-b4ee-8fabfdede7ab', 'message_uuid': '8552328f-1c69-fc6e-9249-5c721e8f55d4', 'message_id': 712312064, 'number_id': 182, 'inserted_at': '2023-12-24 03:39:24.503', 'updated_at': '2023-12-24 03:39:24.503'}  ... displaying 10 of 32946 total bound parameter sets ...  {'id': 260605748, 'status': 'failed', 'timestamp': '2022-03-25 11:04:00.000', 'uuid': 'ca9b67f0-1730-4911-9767-78595b0ec77e', 'message_uuid': '0a0d0299-6c54-22dc-72df-ad87ede36f5b', 'message_id': 278124790, 'number_id': 182, 'inserted_at': '2022-03-25 11:04:01.509', 'updated_at': '2022-03-25 11:04:01.509'}, {'id': 265494229, 'status': 'failed', 'timestamp': '2022-04-29 10:29:51.000', 'uuid': 'dbba7af2-2c35-4aa2-a322-f29494a316b7', 'message_uuid': '4d8039a0-1231-278b-2dba-5d3fe71a1b57', 'message_id': 285241851, 'number_id': 182, 'inserted_at': '2022-04-29 10:29:51.575', 'updated_at': '2022-04-29 10:29:51.575'})]
(Background on this error at: https://sqlalche.me/e/14/f405)
[2024-12-09T01:19:29.529+0000] {taskinstance.py:1225} INFO - Marking task as FAILED. dag_id=data_ingestion_dag, task_id=task_ingest_statuses_data, run_id=manual__2024-12-09T01:19:14.466321+00:00, execution_date=20241209T011914, start_date=20241209T011916, end_date=20241209T011929
[2024-12-09T01:19:29.548+0000] {taskinstance.py:340} INFO - ::group::Post task execution logs
[2024-12-09T01:19:29.549+0000] {standard_task_runner.py:124} ERROR - Failed to execute job 49 for task task_ingest_statuses_data ((psycopg2.errors.UndefinedColumn) column "message_id" of relation "l0_statuses" does not exist
LINE 1: ...tuses (id, status, timestamp, uuid, message_uuid, message_id...
                                                             ^

[SQL: INSERT INTO l0_statuses (id, status, timestamp, uuid, message_uuid, message_id, number_id, inserted_at, updated_at) VALUES (%(id)s, %(status)s, %(timestamp)s, %(uuid)s, %(message_uuid)s, %(message_id)s, %(number_id)s, %(inserted_at)s, %(updated_at)s)]
[parameters: ({'id': 121404643, 'status': 'delivered', 'timestamp': '2020-04-02 16:34:02.369', 'uuid': '2785b584-d41d-452f-9951-1dd7bcbc40f8', 'message_uuid': '994f8115-d94f-f343-f0f7-795e18de38ae', 'message_id': 47972352, 'number_id': 182, 'inserted_at': '2020-04-02 16:34:03.997', 'updated_at': '2020-04-02 16:34:03.997'}, {'id': 121404663, 'status': 'read', 'timestamp': '2020-04-02 16:34:28.000', 'uuid': 'c2f01ea5-8985-4adf-ae12-510a72295bf9', 'message_uuid': '994f8115-d94f-f343-f0f7-795e18de38ae', 'message_id': 47972352, 'number_id': 182, 'inserted_at': '2020-04-02 16:34:39.876', 'updated_at': '2020-04-02 16:34:39.876'}, {'id': 121370160, 'status': 'sent', 'timestamp': '2020-04-01 02:31:29.303', 'uuid': 'cbdb8720-30ee-4144-96f4-6092a9b0ce42', 'message_uuid': '994f8115-d94f-f343-f0f7-795e18de38ae', 'message_id': 47972352, 'number_id': 182, 'inserted_at': '2020-04-01 02:31:29.303', 'updated_at': '2020-04-01 02:31:29.303'}, {'id': 523246060, 'status': 'delivered', 'timestamp': '2023-08-29 03:31:27.000', 'uuid': '268a88d4-0e40-49e7-ac6c-284c73bc2a67', 'message_uuid': '8847b330-1289-336e-56f5-d4909950a689', 'message_id': 497877760, 'number_id': 182, 'inserted_at': '2023-08-29 03:31:27.463', 'updated_at': '2023-08-29 03:31:27.463'}, {'id': 523245973, 'status': 'sent', 'timestamp': '2023-08-29 03:31:25.000', 'uuid': 'f3a253de-3819-4f36-83a8-143d939eef02', 'message_uuid': '8847b330-1289-336e-56f5-d4909950a689', 'message_id': 497877760, 'number_id': 182, 'inserted_at': '2023-08-29 03:31:25.843', 'updated_at': '2023-08-29 03:31:25.843'}, {'id': 523253496, 'status': 'read', 'timestamp': '2023-08-29 03:42:16.000', 'uuid': '6af45bc5-896f-41cb-8bd7-ca8d721be83d', 'message_uuid': '8847b330-1289-336e-56f5-d4909950a689', 'message_id': 497877760, 'number_id': 182, 'inserted_at': '2023-08-29 03:42:16.649', 'updated_at': '2023-08-29 03:42:16.649'}, {'id': 772422679, 'status': 'sent', 'timestamp': '2023-12-24 03:30:14.000', 'uuid': '04fd5533-5e7d-4224-9d53-f532889eb54b', 'message_uuid': '8552328f-1c69-fc6e-9249-5c721e8f55d4', 'message_id': 712312064, 'number_id': 182, 'inserted_at': '2023-12-24 03:30:15.043', 'updated_at': '2023-12-24 03:30:15.043'}, {'id': 772429767, 'status': 'read', 'timestamp': '2023-12-24 03:39:24.000', 'uuid': '87768e3a-f5b2-4cec-b4ee-8fabfdede7ab', 'message_uuid': '8552328f-1c69-fc6e-9249-5c721e8f55d4', 'message_id': 712312064, 'number_id': 182, 'inserted_at': '2023-12-24 03:39:24.503', 'updated_at': '2023-12-24 03:39:24.503'}  ... displaying 10 of 32946 total bound parameter sets ...  {'id': 260605748, 'status': 'failed', 'timestamp': '2022-03-25 11:04:00.000', 'uuid': 'ca9b67f0-1730-4911-9767-78595b0ec77e', 'message_uuid': '0a0d0299-6c54-22dc-72df-ad87ede36f5b', 'message_id': 278124790, 'number_id': 182, 'inserted_at': '2022-03-25 11:04:01.509', 'updated_at': '2022-03-25 11:04:01.509'}, {'id': 265494229, 'status': 'failed', 'timestamp': '2022-04-29 10:29:51.000', 'uuid': 'dbba7af2-2c35-4aa2-a322-f29494a316b7', 'message_uuid': '4d8039a0-1231-278b-2dba-5d3fe71a1b57', 'message_id': 285241851, 'number_id': 182, 'inserted_at': '2022-04-29 10:29:51.575', 'updated_at': '2022-04-29 10:29:51.575'})]
(Background on this error at: https://sqlalche.me/e/14/f405); 839)
Traceback (most recent call last):
  File "/home/airflow/.local/lib/python3.12/site-packages/sqlalchemy/engine/base.py", line 1890, in _execute_context
    self.dialect.do_executemany(
  File "/home/airflow/.local/lib/python3.12/site-packages/sqlalchemy/dialects/postgresql/psycopg2.py", line 982, in do_executemany
    context._psycopg2_fetched_rows = xtras.execute_values(
                                     ^^^^^^^^^^^^^^^^^^^^^
  File "/home/airflow/.local/lib/python3.12/site-packages/psycopg2/extras.py", line 1299, in execute_values
    cur.execute(b''.join(parts))
psycopg2.errors.UndefinedColumn: column "message_id" of relation "l0_statuses" does not exist
LINE 1: ...tuses (id, status, timestamp, uuid, message_uuid, message_id...
                                                             ^


The above exception was the direct cause of the following exception:

Traceback (most recent call last):
  File "/home/airflow/.local/lib/python3.12/site-packages/airflow/task/task_runner/standard_task_runner.py", line 117, in _start_by_fork
    ret = args.func(args, dag=self.dag)
          ^^^^^^^^^^^^^^^^^^^^^^^^^^^^^
  File "/home/airflow/.local/lib/python3.12/site-packages/airflow/cli/cli_config.py", line 49, in command
    return func(*args, **kwargs)
           ^^^^^^^^^^^^^^^^^^^^^
  File "/home/airflow/.local/lib/python3.12/site-packages/airflow/utils/cli.py", line 116, in wrapper
    return f(*args, **kwargs)
           ^^^^^^^^^^^^^^^^^^
  File "/home/airflow/.local/lib/python3.12/site-packages/airflow/cli/commands/task_command.py", line 483, in task_run
    task_return_code = _run_task_by_selected_method(args, _dag, ti)
                       ^^^^^^^^^^^^^^^^^^^^^^^^^^^^^^^^^^^^^^^^^^^^
  File "/home/airflow/.local/lib/python3.12/site-packages/airflow/cli/commands/task_command.py", line 256, in _run_task_by_selected_method
    return _run_raw_task(args, ti)
           ^^^^^^^^^^^^^^^^^^^^^^^
  File "/home/airflow/.local/lib/python3.12/site-packages/airflow/cli/commands/task_command.py", line 341, in _run_raw_task
    return ti._run_raw_task(
           ^^^^^^^^^^^^^^^^^
  File "/home/airflow/.local/lib/python3.12/site-packages/airflow/utils/session.py", line 97, in wrapper
    return func(*args, session=session, **kwargs)
           ^^^^^^^^^^^^^^^^^^^^^^^^^^^^^^^^^^^^^^
  File "/home/airflow/.local/lib/python3.12/site-packages/airflow/models/taskinstance.py", line 3005, in _run_raw_task
    return _run_raw_task(
           ^^^^^^^^^^^^^^
  File "/home/airflow/.local/lib/python3.12/site-packages/airflow/models/taskinstance.py", line 273, in _run_raw_task
    TaskInstance._execute_task_with_callbacks(
  File "/home/airflow/.local/lib/python3.12/site-packages/airflow/models/taskinstance.py", line 3159, in _execute_task_with_callbacks
    result = self._execute_task(context, task_orig)
             ^^^^^^^^^^^^^^^^^^^^^^^^^^^^^^^^^^^^^^
  File "/home/airflow/.local/lib/python3.12/site-packages/airflow/models/taskinstance.py", line 3183, in _execute_task
    return _execute_task(self, context, task_orig)
           ^^^^^^^^^^^^^^^^^^^^^^^^^^^^^^^^^^^^^^^
  File "/home/airflow/.local/lib/python3.12/site-packages/airflow/models/taskinstance.py", line 767, in _execute_task
    result = _execute_callable(context=context, **execute_callable_kwargs)
             ^^^^^^^^^^^^^^^^^^^^^^^^^^^^^^^^^^^^^^^^^^^^^^^^^^^^^^^^^^^^^
  File "/home/airflow/.local/lib/python3.12/site-packages/airflow/models/taskinstance.py", line 733, in _execute_callable
    return ExecutionCallableRunner(
           ^^^^^^^^^^^^^^^^^^^^^^^^
  File "/home/airflow/.local/lib/python3.12/site-packages/airflow/utils/operator_helpers.py", line 252, in run
    return self.func(*args, **kwargs)
           ^^^^^^^^^^^^^^^^^^^^^^^^^^
  File "/home/airflow/.local/lib/python3.12/site-packages/airflow/models/baseoperator.py", line 417, in wrapper
    return func(self, *args, **kwargs)
           ^^^^^^^^^^^^^^^^^^^^^^^^^^^
  File "/home/airflow/.local/lib/python3.12/site-packages/airflow/operators/python.py", line 238, in execute
    return_value = self.execute_callable()
                   ^^^^^^^^^^^^^^^^^^^^^^^
  File "/home/airflow/.local/lib/python3.12/site-packages/airflow/operators/python.py", line 256, in execute_callable
    return runner.run(*self.op_args, **self.op_kwargs)
           ^^^^^^^^^^^^^^^^^^^^^^^^^^^^^^^^^^^^^^^^^^^
  File "/home/airflow/.local/lib/python3.12/site-packages/airflow/utils/operator_helpers.py", line 252, in run
    return self.func(*args, **kwargs)
           ^^^^^^^^^^^^^^^^^^^^^^^^^^
  File "/opt/airflow/resources/util_read_insert_data.py", line 56, in load_excel_to_db
    cleaned_data.to_sql(table_name, engine, if_exists='append', index=False)
  File "/home/airflow/.local/lib/python3.12/site-packages/pandas/util/_decorators.py", line 333, in wrapper
    return func(*args, **kwargs)
           ^^^^^^^^^^^^^^^^^^^^^
  File "/home/airflow/.local/lib/python3.12/site-packages/pandas/core/generic.py", line 3008, in to_sql
    return sql.to_sql(
           ^^^^^^^^^^^
  File "/home/airflow/.local/lib/python3.12/site-packages/pandas/io/sql.py", line 788, in to_sql
    return pandas_sql.to_sql(
           ^^^^^^^^^^^^^^^^^^
  File "/home/airflow/.local/lib/python3.12/site-packages/pandas/io/sql.py", line 1958, in to_sql
    total_inserted = sql_engine.insert_records(
                     ^^^^^^^^^^^^^^^^^^^^^^^^^^
  File "/home/airflow/.local/lib/python3.12/site-packages/pandas/io/sql.py", line 1507, in insert_records
    raise err
  File "/home/airflow/.local/lib/python3.12/site-packages/pandas/io/sql.py", line 1498, in insert_records
    return table.insert(chunksize=chunksize, method=method)
           ^^^^^^^^^^^^^^^^^^^^^^^^^^^^^^^^^^^^^^^^^^^^^^^^
  File "/home/airflow/.local/lib/python3.12/site-packages/pandas/io/sql.py", line 1059, in insert
    num_inserted = exec_insert(conn, keys, chunk_iter)
                   ^^^^^^^^^^^^^^^^^^^^^^^^^^^^^^^^^^^
  File "/home/airflow/.local/lib/python3.12/site-packages/pandas/io/sql.py", line 951, in _execute_insert
    result = conn.execute(self.table.insert(), data)
             ^^^^^^^^^^^^^^^^^^^^^^^^^^^^^^^^^^^^^^^
  File "/home/airflow/.local/lib/python3.12/site-packages/sqlalchemy/engine/base.py", line 1385, in execute
    return meth(self, multiparams, params, _EMPTY_EXECUTION_OPTS)
           ^^^^^^^^^^^^^^^^^^^^^^^^^^^^^^^^^^^^^^^^^^^^^^^^^^^^^^
  File "/home/airflow/.local/lib/python3.12/site-packages/sqlalchemy/sql/elements.py", line 334, in _execute_on_connection
    return connection._execute_clauseelement(
           ^^^^^^^^^^^^^^^^^^^^^^^^^^^^^^^^^^
  File "/home/airflow/.local/lib/python3.12/site-packages/sqlalchemy/engine/base.py", line 1577, in _execute_clauseelement
    ret = self._execute_context(
          ^^^^^^^^^^^^^^^^^^^^^^
  File "/home/airflow/.local/lib/python3.12/site-packages/sqlalchemy/engine/base.py", line 1953, in _execute_context
    self._handle_dbapi_exception(
  File "/home/airflow/.local/lib/python3.12/site-packages/sqlalchemy/engine/base.py", line 2134, in _handle_dbapi_exception
    util.raise_(
  File "/home/airflow/.local/lib/python3.12/site-packages/sqlalchemy/util/compat.py", line 211, in raise_
    raise exception
  File "/home/airflow/.local/lib/python3.12/site-packages/sqlalchemy/engine/base.py", line 1890, in _execute_context
    self.dialect.do_executemany(
  File "/home/airflow/.local/lib/python3.12/site-packages/sqlalchemy/dialects/postgresql/psycopg2.py", line 982, in do_executemany
    context._psycopg2_fetched_rows = xtras.execute_values(
                                     ^^^^^^^^^^^^^^^^^^^^^
  File "/home/airflow/.local/lib/python3.12/site-packages/psycopg2/extras.py", line 1299, in execute_values
    cur.execute(b''.join(parts))
sqlalchemy.exc.ProgrammingError: (psycopg2.errors.UndefinedColumn) column "message_id" of relation "l0_statuses" does not exist
LINE 1: ...tuses (id, status, timestamp, uuid, message_uuid, message_id...
                                                             ^

[SQL: INSERT INTO l0_statuses (id, status, timestamp, uuid, message_uuid, message_id, number_id, inserted_at, updated_at) VALUES (%(id)s, %(status)s, %(timestamp)s, %(uuid)s, %(message_uuid)s, %(message_id)s, %(number_id)s, %(inserted_at)s, %(updated_at)s)]
[parameters: ({'id': 121404643, 'status': 'delivered', 'timestamp': '2020-04-02 16:34:02.369', 'uuid': '2785b584-d41d-452f-9951-1dd7bcbc40f8', 'message_uuid': '994f8115-d94f-f343-f0f7-795e18de38ae', 'message_id': 47972352, 'number_id': 182, 'inserted_at': '2020-04-02 16:34:03.997', 'updated_at': '2020-04-02 16:34:03.997'}, {'id': 121404663, 'status': 'read', 'timestamp': '2020-04-02 16:34:28.000', 'uuid': 'c2f01ea5-8985-4adf-ae12-510a72295bf9', 'message_uuid': '994f8115-d94f-f343-f0f7-795e18de38ae', 'message_id': 47972352, 'number_id': 182, 'inserted_at': '2020-04-02 16:34:39.876', 'updated_at': '2020-04-02 16:34:39.876'}, {'id': 121370160, 'status': 'sent', 'timestamp': '2020-04-01 02:31:29.303', 'uuid': 'cbdb8720-30ee-4144-96f4-6092a9b0ce42', 'message_uuid': '994f8115-d94f-f343-f0f7-795e18de38ae', 'message_id': 47972352, 'number_id': 182, 'inserted_at': '2020-04-01 02:31:29.303', 'updated_at': '2020-04-01 02:31:29.303'}, {'id': 523246060, 'status': 'delivered', 'timestamp': '2023-08-29 03:31:27.000', 'uuid': '268a88d4-0e40-49e7-ac6c-284c73bc2a67', 'message_uuid': '8847b330-1289-336e-56f5-d4909950a689', 'message_id': 497877760, 'number_id': 182, 'inserted_at': '2023-08-29 03:31:27.463', 'updated_at': '2023-08-29 03:31:27.463'}, {'id': 523245973, 'status': 'sent', 'timestamp': '2023-08-29 03:31:25.000', 'uuid': 'f3a253de-3819-4f36-83a8-143d939eef02', 'message_uuid': '8847b330-1289-336e-56f5-d4909950a689', 'message_id': 497877760, 'number_id': 182, 'inserted_at': '2023-08-29 03:31:25.843', 'updated_at': '2023-08-29 03:31:25.843'}, {'id': 523253496, 'status': 'read', 'timestamp': '2023-08-29 03:42:16.000', 'uuid': '6af45bc5-896f-41cb-8bd7-ca8d721be83d', 'message_uuid': '8847b330-1289-336e-56f5-d4909950a689', 'message_id': 497877760, 'number_id': 182, 'inserted_at': '2023-08-29 03:42:16.649', 'updated_at': '2023-08-29 03:42:16.649'}, {'id': 772422679, 'status': 'sent', 'timestamp': '2023-12-24 03:30:14.000', 'uuid': '04fd5533-5e7d-4224-9d53-f532889eb54b', 'message_uuid': '8552328f-1c69-fc6e-9249-5c721e8f55d4', 'message_id': 712312064, 'number_id': 182, 'inserted_at': '2023-12-24 03:30:15.043', 'updated_at': '2023-12-24 03:30:15.043'}, {'id': 772429767, 'status': 'read', 'timestamp': '2023-12-24 03:39:24.000', 'uuid': '87768e3a-f5b2-4cec-b4ee-8fabfdede7ab', 'message_uuid': '8552328f-1c69-fc6e-9249-5c721e8f55d4', 'message_id': 712312064, 'number_id': 182, 'inserted_at': '2023-12-24 03:39:24.503', 'updated_at': '2023-12-24 03:39:24.503'}  ... displaying 10 of 32946 total bound parameter sets ...  {'id': 260605748, 'status': 'failed', 'timestamp': '2022-03-25 11:04:00.000', 'uuid': 'ca9b67f0-1730-4911-9767-78595b0ec77e', 'message_uuid': '0a0d0299-6c54-22dc-72df-ad87ede36f5b', 'message_id': 278124790, 'number_id': 182, 'inserted_at': '2022-03-25 11:04:01.509', 'updated_at': '2022-03-25 11:04:01.509'}, {'id': 265494229, 'status': 'failed', 'timestamp': '2022-04-29 10:29:51.000', 'uuid': 'dbba7af2-2c35-4aa2-a322-f29494a316b7', 'message_uuid': '4d8039a0-1231-278b-2dba-5d3fe71a1b57', 'message_id': 285241851, 'number_id': 182, 'inserted_at': '2022-04-29 10:29:51.575', 'updated_at': '2022-04-29 10:29:51.575'})]
(Background on this error at: https://sqlalche.me/e/14/f405)
[2024-12-09T01:19:29.585+0000] {local_task_job_runner.py:266} INFO - Task exited with return code 1
[2024-12-09T01:19:29.604+0000] {taskinstance.py:3895} INFO - 0 downstream tasks scheduled from follow-on schedule check
[2024-12-09T01:19:29.606+0000] {local_task_job_runner.py:245} INFO - ::endgroup::
