[2024-12-08T06:51:06.826+0000] {local_task_job_runner.py:123} INFO - ::group::Pre task execution logs
[2024-12-08T06:51:06.843+0000] {taskinstance.py:2613} INFO - Dependencies all met for dep_context=non-requeueable deps ti=<TaskInstance: data_ingestion_dag.task_ingest_messages_data manual__2024-12-08T06:51:05.597230+00:00 [queued]>
[2024-12-08T06:51:06.849+0000] {taskinstance.py:2613} INFO - Dependencies all met for dep_context=requeueable deps ti=<TaskInstance: data_ingestion_dag.task_ingest_messages_data manual__2024-12-08T06:51:05.597230+00:00 [queued]>
[2024-12-08T06:51:06.850+0000] {taskinstance.py:2866} INFO - Starting attempt 1 of 1
[2024-12-08T06:51:06.864+0000] {taskinstance.py:2889} INFO - Executing <Task(PythonOperator): task_ingest_messages_data> on 2024-12-08 06:51:05.597230+00:00
[2024-12-08T06:51:06.869+0000] {warnings.py:112} WARNING - /home/***/.local/lib/python3.12/site-packages/***/task/task_runner/standard_task_runner.py:70: DeprecationWarning: This process (pid=85) is multi-threaded, use of fork() may lead to deadlocks in the child.
  pid = os.fork()

[2024-12-08T06:51:06.871+0000] {standard_task_runner.py:72} INFO - Started process 87 to run task
[2024-12-08T06:51:06.872+0000] {standard_task_runner.py:104} INFO - Running: ['***', 'tasks', 'run', 'data_ingestion_dag', 'task_ingest_messages_data', 'manual__2024-12-08T06:51:05.597230+00:00', '--job-id', '35', '--raw', '--subdir', 'DAGS_FOLDER/test.py', '--cfg-path', '/tmp/tmpzaamw4c5']
[2024-12-08T06:51:06.874+0000] {standard_task_runner.py:105} INFO - Job 35: Subtask task_ingest_messages_data
[2024-12-08T06:51:06.913+0000] {task_command.py:467} INFO - Running <TaskInstance: data_ingestion_dag.task_ingest_messages_data manual__2024-12-08T06:51:05.597230+00:00 [running]> on host ad379471be2c
[2024-12-08T06:51:07.124+0000] {taskinstance.py:3132} INFO - Exporting env vars: AIRFLOW_CTX_DAG_OWNER='***' AIRFLOW_CTX_DAG_ID='data_ingestion_dag' AIRFLOW_CTX_TASK_ID='task_ingest_messages_data' AIRFLOW_CTX_EXECUTION_DATE='2024-12-08T06:51:05.597230+00:00' AIRFLOW_CTX_TRY_NUMBER='1' AIRFLOW_CTX_DAG_RUN_ID='manual__2024-12-08T06:51:05.597230+00:00'
[2024-12-08T06:51:07.125+0000] {taskinstance.py:731} INFO - ::endgroup::
[2024-12-08T06:51:11.611+0000] {base.py:84} INFO - Retrieving connection 'external_postgres'
[2024-12-08T06:51:11.675+0000] {warnings.py:112} WARNING - /opt/***/resources/util_read_insert_data.py:21: UserWarning: pandas only supports SQLAlchemy connectable (engine/connection) or database string URI or sqlite3 DBAPI2 connection. Other DBAPI2 objects are not tested. Please consider using SQLAlchemy.
  df.to_sql(table_name, postgres_hook.get_conn(), if_exists='append', index=False)

[2024-12-08T06:51:11.681+0000] {taskinstance.py:3311} ERROR - Task failed with exception
Traceback (most recent call last):
  File "/home/airflow/.local/lib/python3.12/site-packages/pandas/io/sql.py", line 2262, in execute
    cur.execute(sql, *args)
psycopg2.errors.SyntaxError: syntax error at or near ";"
LINE 8:             AND name=?;
                              ^


The above exception was the direct cause of the following exception:

Traceback (most recent call last):
  File "/home/airflow/.local/lib/python3.12/site-packages/airflow/models/taskinstance.py", line 767, in _execute_task
    result = _execute_callable(context=context, **execute_callable_kwargs)
             ^^^^^^^^^^^^^^^^^^^^^^^^^^^^^^^^^^^^^^^^^^^^^^^^^^^^^^^^^^^^^
  File "/home/airflow/.local/lib/python3.12/site-packages/airflow/models/taskinstance.py", line 733, in _execute_callable
    return ExecutionCallableRunner(
           ^^^^^^^^^^^^^^^^^^^^^^^^
  File "/home/airflow/.local/lib/python3.12/site-packages/airflow/utils/operator_helpers.py", line 252, in run
    return self.func(*args, **kwargs)
           ^^^^^^^^^^^^^^^^^^^^^^^^^^
  File "/home/airflow/.local/lib/python3.12/site-packages/airflow/models/baseoperator.py", line 417, in wrapper
    return func(self, *args, **kwargs)
           ^^^^^^^^^^^^^^^^^^^^^^^^^^^
  File "/home/airflow/.local/lib/python3.12/site-packages/airflow/operators/python.py", line 238, in execute
    return_value = self.execute_callable()
                   ^^^^^^^^^^^^^^^^^^^^^^^
  File "/home/airflow/.local/lib/python3.12/site-packages/airflow/operators/python.py", line 256, in execute_callable
    return runner.run(*self.op_args, **self.op_kwargs)
           ^^^^^^^^^^^^^^^^^^^^^^^^^^^^^^^^^^^^^^^^^^^
  File "/home/airflow/.local/lib/python3.12/site-packages/airflow/utils/operator_helpers.py", line 252, in run
    return self.func(*args, **kwargs)
           ^^^^^^^^^^^^^^^^^^^^^^^^^^
  File "/opt/airflow/resources/util_read_insert_data.py", line 21, in load_excel_to_db
    df.to_sql(table_name, postgres_hook.get_conn(), if_exists='append', index=False)
  File "/home/airflow/.local/lib/python3.12/site-packages/pandas/util/_decorators.py", line 333, in wrapper
    return func(*args, **kwargs)
           ^^^^^^^^^^^^^^^^^^^^^
  File "/home/airflow/.local/lib/python3.12/site-packages/pandas/core/generic.py", line 3008, in to_sql
    return sql.to_sql(
           ^^^^^^^^^^^
  File "/home/airflow/.local/lib/python3.12/site-packages/pandas/io/sql.py", line 788, in to_sql
    return pandas_sql.to_sql(
           ^^^^^^^^^^^^^^^^^^
  File "/home/airflow/.local/lib/python3.12/site-packages/pandas/io/sql.py", line 2438, in to_sql
    table.create()
  File "/home/airflow/.local/lib/python3.12/site-packages/pandas/io/sql.py", line 925, in create
    if self.exists():
       ^^^^^^^^^^^^^
  File "/home/airflow/.local/lib/python3.12/site-packages/pandas/io/sql.py", line 911, in exists
    return self.pd_sql.has_table(self.name, self.schema)
           ^^^^^^^^^^^^^^^^^^^^^^^^^^^^^^^^^^^^^^^^^^^^^
  File "/home/airflow/.local/lib/python3.12/site-packages/pandas/io/sql.py", line 2453, in has_table
    return len(self.execute(query, [name]).fetchall()) > 0
               ^^^^^^^^^^^^^^^^^^^^^^^^^^^
  File "/home/airflow/.local/lib/python3.12/site-packages/pandas/io/sql.py", line 2274, in execute
    raise ex from exc
pandas.errors.DatabaseError: Execution failed on sql '
        SELECT
            name
        FROM
            sqlite_master
        WHERE
            type IN ('table', 'view')
            AND name=?;
        ': syntax error at or near ";"
LINE 8:             AND name=?;
                              ^

[2024-12-08T06:51:11.690+0000] {taskinstance.py:1225} INFO - Marking task as FAILED. dag_id=data_ingestion_dag, task_id=task_ingest_messages_data, run_id=manual__2024-12-08T06:51:05.597230+00:00, execution_date=20241208T065105, start_date=20241208T065106, end_date=20241208T065111
[2024-12-08T06:51:11.700+0000] {taskinstance.py:340} INFO - ::group::Post task execution logs
[2024-12-08T06:51:11.701+0000] {standard_task_runner.py:124} ERROR - Failed to execute job 35 for task task_ingest_messages_data (Execution failed on sql '
        SELECT
            name
        FROM
            sqlite_master
        WHERE
            type IN ('table', 'view')
            AND name=?;
        ': syntax error at or near ";"
LINE 8:             AND name=?;
                              ^
; 87)
Traceback (most recent call last):
  File "/home/airflow/.local/lib/python3.12/site-packages/pandas/io/sql.py", line 2262, in execute
    cur.execute(sql, *args)
psycopg2.errors.SyntaxError: syntax error at or near ";"
LINE 8:             AND name=?;
                              ^


The above exception was the direct cause of the following exception:

Traceback (most recent call last):
  File "/home/airflow/.local/lib/python3.12/site-packages/airflow/task/task_runner/standard_task_runner.py", line 117, in _start_by_fork
    ret = args.func(args, dag=self.dag)
          ^^^^^^^^^^^^^^^^^^^^^^^^^^^^^
  File "/home/airflow/.local/lib/python3.12/site-packages/airflow/cli/cli_config.py", line 49, in command
    return func(*args, **kwargs)
           ^^^^^^^^^^^^^^^^^^^^^
  File "/home/airflow/.local/lib/python3.12/site-packages/airflow/utils/cli.py", line 116, in wrapper
    return f(*args, **kwargs)
           ^^^^^^^^^^^^^^^^^^
  File "/home/airflow/.local/lib/python3.12/site-packages/airflow/cli/commands/task_command.py", line 483, in task_run
    task_return_code = _run_task_by_selected_method(args, _dag, ti)
                       ^^^^^^^^^^^^^^^^^^^^^^^^^^^^^^^^^^^^^^^^^^^^
  File "/home/airflow/.local/lib/python3.12/site-packages/airflow/cli/commands/task_command.py", line 256, in _run_task_by_selected_method
    return _run_raw_task(args, ti)
           ^^^^^^^^^^^^^^^^^^^^^^^
  File "/home/airflow/.local/lib/python3.12/site-packages/airflow/cli/commands/task_command.py", line 341, in _run_raw_task
    return ti._run_raw_task(
           ^^^^^^^^^^^^^^^^^
  File "/home/airflow/.local/lib/python3.12/site-packages/airflow/utils/session.py", line 97, in wrapper
    return func(*args, session=session, **kwargs)
           ^^^^^^^^^^^^^^^^^^^^^^^^^^^^^^^^^^^^^^
  File "/home/airflow/.local/lib/python3.12/site-packages/airflow/models/taskinstance.py", line 3005, in _run_raw_task
    return _run_raw_task(
           ^^^^^^^^^^^^^^
  File "/home/airflow/.local/lib/python3.12/site-packages/airflow/models/taskinstance.py", line 273, in _run_raw_task
    TaskInstance._execute_task_with_callbacks(
  File "/home/airflow/.local/lib/python3.12/site-packages/airflow/models/taskinstance.py", line 3159, in _execute_task_with_callbacks
    result = self._execute_task(context, task_orig)
             ^^^^^^^^^^^^^^^^^^^^^^^^^^^^^^^^^^^^^^
  File "/home/airflow/.local/lib/python3.12/site-packages/airflow/models/taskinstance.py", line 3183, in _execute_task
    return _execute_task(self, context, task_orig)
           ^^^^^^^^^^^^^^^^^^^^^^^^^^^^^^^^^^^^^^^
  File "/home/airflow/.local/lib/python3.12/site-packages/airflow/models/taskinstance.py", line 767, in _execute_task
    result = _execute_callable(context=context, **execute_callable_kwargs)
             ^^^^^^^^^^^^^^^^^^^^^^^^^^^^^^^^^^^^^^^^^^^^^^^^^^^^^^^^^^^^^
  File "/home/airflow/.local/lib/python3.12/site-packages/airflow/models/taskinstance.py", line 733, in _execute_callable
    return ExecutionCallableRunner(
           ^^^^^^^^^^^^^^^^^^^^^^^^
  File "/home/airflow/.local/lib/python3.12/site-packages/airflow/utils/operator_helpers.py", line 252, in run
    return self.func(*args, **kwargs)
           ^^^^^^^^^^^^^^^^^^^^^^^^^^
  File "/home/airflow/.local/lib/python3.12/site-packages/airflow/models/baseoperator.py", line 417, in wrapper
    return func(self, *args, **kwargs)
           ^^^^^^^^^^^^^^^^^^^^^^^^^^^
  File "/home/airflow/.local/lib/python3.12/site-packages/airflow/operators/python.py", line 238, in execute
    return_value = self.execute_callable()
                   ^^^^^^^^^^^^^^^^^^^^^^^
  File "/home/airflow/.local/lib/python3.12/site-packages/airflow/operators/python.py", line 256, in execute_callable
    return runner.run(*self.op_args, **self.op_kwargs)
           ^^^^^^^^^^^^^^^^^^^^^^^^^^^^^^^^^^^^^^^^^^^
  File "/home/airflow/.local/lib/python3.12/site-packages/airflow/utils/operator_helpers.py", line 252, in run
    return self.func(*args, **kwargs)
           ^^^^^^^^^^^^^^^^^^^^^^^^^^
  File "/opt/airflow/resources/util_read_insert_data.py", line 21, in load_excel_to_db
    df.to_sql(table_name, postgres_hook.get_conn(), if_exists='append', index=False)
  File "/home/airflow/.local/lib/python3.12/site-packages/pandas/util/_decorators.py", line 333, in wrapper
    return func(*args, **kwargs)
           ^^^^^^^^^^^^^^^^^^^^^
  File "/home/airflow/.local/lib/python3.12/site-packages/pandas/core/generic.py", line 3008, in to_sql
    return sql.to_sql(
           ^^^^^^^^^^^
  File "/home/airflow/.local/lib/python3.12/site-packages/pandas/io/sql.py", line 788, in to_sql
    return pandas_sql.to_sql(
           ^^^^^^^^^^^^^^^^^^
  File "/home/airflow/.local/lib/python3.12/site-packages/pandas/io/sql.py", line 2438, in to_sql
    table.create()
  File "/home/airflow/.local/lib/python3.12/site-packages/pandas/io/sql.py", line 925, in create
    if self.exists():
       ^^^^^^^^^^^^^
  File "/home/airflow/.local/lib/python3.12/site-packages/pandas/io/sql.py", line 911, in exists
    return self.pd_sql.has_table(self.name, self.schema)
           ^^^^^^^^^^^^^^^^^^^^^^^^^^^^^^^^^^^^^^^^^^^^^
  File "/home/airflow/.local/lib/python3.12/site-packages/pandas/io/sql.py", line 2453, in has_table
    return len(self.execute(query, [name]).fetchall()) > 0
               ^^^^^^^^^^^^^^^^^^^^^^^^^^^
  File "/home/airflow/.local/lib/python3.12/site-packages/pandas/io/sql.py", line 2274, in execute
    raise ex from exc
pandas.errors.DatabaseError: Execution failed on sql '
        SELECT
            name
        FROM
            sqlite_master
        WHERE
            type IN ('table', 'view')
            AND name=?;
        ': syntax error at or near ";"
LINE 8:             AND name=?;
                              ^

[2024-12-08T06:51:11.748+0000] {local_task_job_runner.py:266} INFO - Task exited with return code 1
[2024-12-08T06:51:11.760+0000] {taskinstance.py:3895} INFO - 0 downstream tasks scheduled from follow-on schedule check
[2024-12-08T06:51:11.763+0000] {local_task_job_runner.py:245} INFO - ::endgroup::
